Workbook
Name Slicer_customer_city: #N/A
Name Slicer_customer_state: #N/A
Name Slicer_order_status: #N/A
Name Slicer_payment_type: #N/A
Name Slicer_product_category_name: #N/A

Sheet pivot
A2: Row Labels | B2: Count of order_id | E2: Average of delivery_period | H2: Row Labels | I2: Count of delivery_status | L2: Sum of price | O2: Average of price | R2: Row Labels | S2: Count of order_id | V2: States | W2: orders | Y2: =V2 -> States | Z2: =W2 -> orders | AC2: Row Labels | AD2: Count of order_id | AG2: Cities | AH2: orders | AJ2: =IF(AG2=0,"",AG2) -> Cities | AK2: =IF(AH2=0,"",AH2) -> orders | AM2: Row Labels | AN2: Count of order_id | AQ2: cities | AR2: Average of delivery_period | AT2: =IF(AQ2=0,"",AQ2) -> cities | AU2: =IF(AR2=0,"",AR2) -> Average of delivery_period | AW2: Row Labels | AX2: Average of delivery_period | AZ2: =IF(AW2=0," ",AW2) -> Row Labels | BA2: =IF(AX2=0," ",AX2) -> Average of delivery_period | BC2: Row Labels | BD2: Count of payment_type | BG2: Row Labels | BH2: Count of order_id | BJ2: =IF(BG2=0,"",BG2) -> Row Labels | BK2: =IF(BH2=0,"",BH2) -> Count of order_id | BM2: Row Labels | BN2: Count of order_id | BQ2: Row Labels | BR2: Count of order_id
A3: approved | B3: 2 | E3: 12.395438 | H3: late delivery | I3: 6738 | L3: 30447873 | O3: 340.90054 | R3: 2016 | V3: São Paulo | W3: 37878 | Y3: =V3 -> São Paulo | Z3: =W3 -> 37878 | AC3: Acre | AD3: 75 | AG3: sao paulo | AH3: 14351 | AJ3: =IF(AG3=0," ",AG3) -> sao paulo | AK3: =IF(AH3=0," ",AH3) -> 14351 | AM3: sao paulo | AN3: 14351 | AQ3: santa cruz de goias | AR3: 125 | AT3: =IF(AQ3=0," ",AQ3) -> santa cruz de goias | AU3: =IF(AR3=0," ",AR3) -> 125 | AW3: iomere | AX3: 3 | AZ3: =IF(AW3=0," ",AW3) -> iomere | BA3: =IF(AX3=0," ",AX3) -> 3 | BC3: credit_card | BD3: 0.73686685 | BG3: toys | BH3: 67026 | BJ3: =IF(BG3=0," ",BG3) -> toys | BK3: =IF(BH3=0," ",BH3) -> 67026 | BM3: security_and_services | BN3: 1 | BQ3: credit_card | BR3: 65814
A4: canceled | B4: 409 | H4: on time delivery | I4: 80689 | R4: Sep | S4: 3 | V4: Rio de Janeiro | W4: 11578 | Y4: =IF(V4=0,"",V4) -> Rio de Janeiro | Z4: =IF(W4=0,"",W4) -> 11578 | AC4: Alagoas | AD4: 342 | AG4: rio de janeiro | AH4: 6248 | AJ4: =IF(AG4=0," ",AG4) -> rio de janeiro | AK4: =IF(AH4=0," ",AH4) -> 6248 | AM4: rio de janeiro | AN4: 6248 | AQ4: adhemar de barros | AR4: 97 | AT4: =IF(AQ4=0," ",AQ4) -> adhemar de barros | AU4: =IF(AR4=0," ",AR4) -> 97 | AW4: quitandinha | AX4: 3 | AZ4: =IF(AW4=0," ",AW4) -> quitandinha | BA4: =IF(AX4=0," ",AX4) -> 3 | BC4: debit_card | BD4: 0.014431905 | BG4: health_beauty | BH4: 2351 | BJ4: =IF(BG4=0," ",BG4) -> health_beauty | BK4: =IF(BH4=0," ",BH4) -> 2351 | BM4: diapers_and_hygiene | BN4: 1 | BQ4: debit_card | BR4: 1289
A5: delivered | B5: 87428 | H5: Grand Total | I5: 87427 | R5: Oct | S5: 289 | V5: Minas Gerais | W5: 10334 | Y5: =IF(V5=0,"",V5) -> Minas Gerais | Z5: =IF(W5=0,"",W5) -> 10334 | AC5: Amapá | AD5: 68 | AG5: belo horizonte | AH5: 2426 | AJ5: =IF(AG5=0," ",AG5) -> belo horizonte | AK5: =IF(AH5=0," ",AH5) -> 2426 | AM5: belo horizonte | AN5: 2426 | AQ5: arace | AR5: 96.333333 | AT5: =IF(AQ5=0," ",AQ5) -> arace | AU5: =IF(AR5=0," ",AR5) -> 96.333333 | AW5: siriji | AX5: 3 | AZ5: =IF(AW5=0," ",AW5) -> siriji | BA5: =IF(AX5=0," ",AX5) -> 3 | BC5: voucher | BD5: 0.054984549 | BG5: bed_bath_table | BH5: 2146 | BJ5: =IF(BG5=0," ",BG5) -> bed_bath_table | BK5: =IF(BH5=0," ",BH5) -> 2146 | BM5: home_comfort_2 | BN5: 1 | BQ5: voucher | BR5: 4910
A6: invoiced | B6: 266 | R6: Dec | S6: 1 | V6: Rio Grande do Sul | W6: 4921 | Y6: =IF(V6=0,"",V6) -> Rio Grande do Sul | Z6: =IF(W6=0,"",W6) -> 4921 | AC6: Amazonas | AD6: 140 | AG6: brasilia | AH6: 1778 | AJ6: =IF(AG6=0," ",AG6) -> brasilia | AK6: =IF(AH6=0," ",AH6) -> 1778 | AM6: brasilia | AN6: 1778 | AQ6: marcelino vieira | AR6: 78 | AT6: =IF(AQ6=0," ",AQ6) -> marcelino vieira | AU6: =IF(AR6=0," ",AR6) -> 78 | AW6: acucena | AX6: 4 | AZ6: =IF(AW6=0," ",AW6) -> acucena | BA6: =IF(AX6=0," ",AX6) -> 4 | BC6: wallet | BD6: 0.19371669 | BG6: sports_leisure | BH6: 1837 | BJ6: =IF(BG6=0," ",BG6) -> sports_leisure | BK6: =IF(BH6=0," ",BH6) -> 1837 | BM6: furniture_mattress_and_upholstery | BN6: 1 | BQ6: wallet | BR6: 17302
A7: processing | B7: 273 | R7: 2017 | V7: Paraná | W7: 4523 | Y7: =IF(V7=0,"",V7) -> Paraná | Z7: =IF(W7=0,"",W7) -> 4523 | AC7: Bahia | AD7: 3088 | AG7: curitiba | AH7: 1421 | AJ7: =IF(AG7=0," ",AG7) -> curitiba | AK7: =IF(AH7=0," ",AH7) -> 1421 | AM7: curitiba | AN7: 1421 | AQ7: aramari | AR7: 76 | AT7: =IF(AQ7=0," ",AQ7) -> aramari | AU7: =IF(AR7=0," ",AR7) -> 76 | AW7: ajuricaba | AX7: 4 | AZ7: =IF(AW7=0," ",AW7) -> ajuricaba | BA7: =IF(AX7=0," ",AX7) -> 4 | BG7: furniture_decor | BH7: 1760 | BJ7: =IF(BG7=0," ",BG7) -> furniture_decor | BK7: =IF(BH7=0," ",BH7) -> 1760 | BM7: fashion_childrens_clothes | BN7: 2 | BQ7: Grand Total | BR7: 89315
A8: shipped | B8: 935 | R8: Jan | S8: 857 | V8: Santa Catarina | W8: 3213 | Y8: =IF(V8=0,"",V8) -> Santa Catarina | Z8: =IF(W8=0,"",W8) -> 3213 | AC8: Ceará | AD8: 1141 | AG8: porto alegre | AH8: 1311 | AM8: porto alegre | AN8: 1311 | AQ8: serra dos dourados | AR8: 75 | AW8: agua doce | AX8: 4 | BG8: computers_accessories | BH8: 1715 | BM8: fashio_female_clothing | BN8: 2
A9: unavailable | B9: 2 | R9: Feb | S9: 1534 | V9: Bahia | W9: 3088 | Y9: =V9 -> Bahia | Z9: =W9 -> 3088 | AC9: Distrito Federal | AD9: 1793 | AG9: campinas | AH9: 1304 | AM9: campinas | AN9: 1304 | AQ9: humildes | AR9: 72 | AW9: cambara do sul | AX9: 4 | BG9: housewares | BH9: 1340 | BM9: fashion_sport | BN9: 3
A10: Grand Total | B10: 89315 | R10: Mar | S10: 2392 | V10: Goiás | W10: 1868 | Y10: =V10 -> Goiás | Z10: =W10 -> 1868 | AC10: Espírito Santo | AD10: 1798 | AG10: salvador | AH10: 1148 | AM10: salvador | AN10: 1148 | AQ10: rubineia | AR10: 64 | AW10: barao de juparana | AX10: 4 | BG10: watches_gifts | BH10: 1196 | BM10: la_cuisine | BN10: 4
R11: Apr | S11: 2156 | V11: Espírito Santo | W11: 1798 | Y11: =V11 -> Espírito Santo | Z11: =W11 -> 1798 | AC11: Goiás | AD11: 1868 | AG11: guarulhos | AH11: 1067 | AM11: guarulhos | AN11: 1067 | AQ11: glaura | AR11: 59 | AW11: contenda | AX11: 4 | BG11: telephony | BH11: 912 | BM11: arts_and_craftmanship | BN11: 4
R12: May | S12: 3407 | V12: Distrito Federal | W12: 1793 | Y12: =V12 -> Distrito Federal | Z12: =W12 -> 1793 | AC12: Maranhão | AD12: 623 | AG12: sao bernardo do campo | AH12: 839 | AM12: sao bernardo do campo | AN12: 839 | AQ12: alto sao joao | AR12: 59 | AW12: imbau | AX12: 4 | BG12: auto | BH12: 829 | BM12: cine_photo | BN12: 5
R13: Jun | S13: 2953 | V13: Pernambuco | W13: 1493 | Y13: =V13 -> Pernambuco | Z13: =W13 -> 1493 | AC13: Mato Grosso | AD13: 848 | AG13: niteroi | AH13: 814 | AM13: niteroi | AN13: 814 | AQ13: quintana | AR13: 57 | AW13: pedra bela | AX13: 4 | BG13: garden_tools | BH13: 807 | BM13: flowers | BN13: 6
R14: Jul | S14: 3781 | V14: Ceará | W14: 1141 | Y14: =V14 -> Ceará | Z14: =W14 -> 1141 | AC14: Mato Grosso do Sul | AD14: 637 | AG14: osasco | AH14: 694 | AM14: osasco | AN14: 694 | AQ14: placas | AR14: 57 | AW14: sao pedro de alcantara | AX14: 4 | BG14: cool_stuff | BH14: 718 | BM14: party_supplies | BN14: 7
R15: Aug | S15: 4028 | V15: Mato Grosso | W15: 848 | Y15: =V15 -> Mato Grosso | Z15: =W15 -> 848 | AC15: Minas Gerais | AD15: 10334 | AG15: santo andre | AH15: 691 | AM15: santo andre | AN15: 691 | AQ15: ourem | AR15: 57 | AW15: sao patricio | AX15: 4 | BG15: perfumery | BH15: 671 | BM15: music | BN15: 7
R16: Sep | S16: 3937 | V16: Pará | W16: 817 | Y16: =V16 -> Pará | Z16: =W16 -> 817 | AC16: Pará | AD16: 817 | AG16: santos | AH16: 662 | AM16: santos | AN16: 662 | AQ16: felicio dos santos | AR16: 55 | AW16: bento de abreu | AX16: 5 | BG16: baby | BH16: 621 | BM16: small_appliances_home_oven_and_coffee | BN16: 9
R17: Oct | S17: 4258 | V17: Mato Grosso do Sul | W17: 637 | Y17: =V17 -> Mato Grosso do Sul | Z17: =W17 -> 637 | AC17: Paraíba | AD17: 497 | AG17: goiania | AH17: 660 | AM17: goiania | AN17: 660 | AQ17: assuncao | AR17: 53 | AW17: caracol | AX17: 5 | BG17: electronics | BH17: 547 | BM17: dvds_blu_ray | BN17: 10
R18: Nov | S18: 6840 | V18: Maranhão | W18: 623 | Y18: =V18 -> Maranhão | Z18: =W18 -> 623 | AC18: Paraná | AD18: 4523 | AG18: sao jose dos campos | AH18: 608 | AM18: sao jose dos campos | AN18: 608 | AQ18: jacareacanga | AR18: 52 | AW18: delfim moreira | AX18: 5 | BG18: office_furniture | BH18: 533 | BM18: books_imported | BN18: 12
R19: Dec | S19: 4981 | V19: Paraíba | W19: 497 | Y19: =V19 -> Paraíba | Z19: =W19 -> 497 | AC19: Pernambuco | AD19: 1493 | AG19: recife | AH19: 588 | AM19: recife | AN19: 588 | AQ19: boa vista do gurupi | AR19: 52 | AW19: embauba | AX19: 5 | BG19: stationery | BH19: 462 | BM19: art | BN19: 13
R20: 2018 | V20: Piauí | W20: 423 | Y20: =V20 -> Piauí | Z20: =W20 -> 423 | AC20: Piauí | AD20: 423 | AG20: fortaleza | AH20: 566 | AM20: fortaleza | AN20: 566 | AQ20: formosa do rio preto | AR20: 51.571429 | AW20: ibira | AX20: 5 | BG20: fashion_bags_accessories | BH20: 408 | BM20: fashion_underwear_beach | BN20: 16
R21: Jan | S21: 6463 | V21: Rio Grande do Norte | W21: 381 | Y21: =V21 -> Rio Grande do Norte | Z21: =W21 -> 381 | AC21: Rio de Janeiro | AD21: 11578 | AG21: sorocaba | AH21: 545 | AM21: sorocaba | AN21: 545 | AQ21: passira | AR21: 50 | AW21: irapua | AX21: 5 | BG21: pet_shop | BH21: 394 | BM21: furniture_bedroom | BN21: 16
R22: Feb | S22: 6069 | V22: Alagoas | W22: 342 | Y22: =V22 -> Alagoas | Z22: =W22 -> 342 | AC22: Rio Grande do Norte | AD22: 381 | AG22: florianopolis | AH22: 540 | AM22: florianopolis | AN22: 540 | AQ22: capinzal do norte | AR22: 50 | AW22: gameleiras | AX22: 5 | BG22: uncategorized | BH22: 308 | BM22: fashion_male_clothing | BN22: 21
R23: Mar | S23: 6508 | V23: Sergipe | W23: 305 | Y23: =V23 -> Sergipe | Z23: =W23 -> 305 | AC23: Rio Grande do Sul | AD23: 4921 | AG23: jundiai | AH23: 527 | AM23: jundiai | AN23: 527 | AQ23: itaporanga d'ajuda | AR23: 49 | AW23: frei gaspar | AX23: 5 | BG23: home_appliances | BH23: 215 | BM23: construction_tools_safety | BN23: 24
R24: Apr | S24: 6200 | V24: Tocantins | W24: 247 | Y24: =V24 -> Tocantins | Z24: =W24 -> 247 | AC24: Rondônia | AD24: 241 | AG24: ribeirao preto | AH24: 475 | AM24: ribeirao preto | AN24: 475 | AQ24: imaculada | AR24: 49 | AW24: guapiara | AX24: 5 | BG24: construction_tools_construction | BH24: 192 | BM24: christmas_supplies | BN24: 27
R25: May | S25: 6163 | V25: Rondônia | W25: 241 | Y25: =V25 -> Rondônia | Z25: =W25 -> 241 | AC25: Roraima | AD25: 43 | AG25: juiz de fora | AH25: 397 | AM25: juiz de fora | AN25: 397 | AQ25: miguel calmon | AR25: 48.25 | AW25: miraguai | AX25: 5 | BG25: luggage_accessories | BH25: 178 | BM25: costruction_tools_tools | BN25: 32
R26: Jun | S26: 5510 | V26: Amazonas | W26: 140 | Y26: =V26 -> Amazonas | Z26: =W26 -> 140 | AC26: Santa Catarina | AD26: 3213 | AG26: contagem | AH26: 390 | AM26: contagem | AN26: 390 | AQ26: vere | AR26: 48 | AW26: meridiano | AX26: 5 | BG26: consoles_games | BH26: 156 | BM26: home_confort | BN26: 40
R27: Jul | S27: 5430 | V27: Acre | W27: 75 | Y27: =V27 -> Acre | Z27: =W27 -> 75 | AC27: São Paulo | AD27: 37878 | AG27: belem | AH27: 378 | AM27: belem | AN27: 378 | AQ27: goncalves dias | AR27: 48 | AW27: nazareno | AX27: 5 | BG27: musical_instruments | BH27: 150 | BM27: fixed_telephony | BN27: 47
R28: Aug | S28: 5555 | V28: Amapá | W28: 68 | Y28: =V28 -> Amapá | Z28: =W28 -> 68 | AC28: Sergipe | AD28: 305 | AG28: nova iguacu | AH28: 376 | AM28: nova iguacu | AN28: 376 | AQ28: duas barras | AR28: 48 | AW28: piquerobi | AX28: 5 | BG28: home_construction | BH28: 131 | BM28: industry_commerce_and_business | BN28: 48
V29: Roraima | W29: 43 | Y29: =V29 -> Roraima | Z29: =W29 -> 43 | AC29: Tocantins | AD29: 247 | AG29: mogi das cruzes | AH29: 369 | AM29: mogi das cruzes | AN29: 369 | AQ29: currais novos | AR29: 47.4 | AW29: rubiacea | AX29: 5 | BG29: small_appliances | BH29: 117 | BM29: signaling_and_security | BN29: 48
AG30: barueri | AH30: 364 | AM30: barueri | AN30: 364 | AQ30: jatauba | AR30: 47 | AW30: roca sales | AX30: 5 | BG30: audio | BH30: 107 | BM30: drinks | BN30: 50
AG31: vitoria | AH31: 355 | AM31: vitoria | AN31: 355 | AQ31: jiquirica | AR31: 47 | AW31: rifaina | AX31: 5 | BG31: market_place | BH31: 84 | BM31: construction_tools_lights | BN31: 51
AG32: praia grande | AH32: 349 | AM32: praia grande | AN32: 349 | AQ32: sao joao de pirabas | AR32: 46.5 | AW32: sananduva | AX32: 5 | BG32: costruction_tools_garden | BH32: 82 | BM32: kitchen_dining_laundry_garden_furniture | BN32: 52
AG33: sao goncalo | AH33: 343 | AM33: sao goncalo | AN33: 343 | AQ33: sao miguel dos campos | AR33: 46.25 | AW33: salto grande | AX33: 5 | BG33: books_general_interest | BH33: 82 | BM33: computers | BN33: 53
AG34: uberlandia | AH34: 319 | AM34: uberlandia | AN34: 319 | AQ34: santa terezinha | AR34: 46 | AW34: sao joao da urtiga | AX34: 5 | BG34: furniture_living_room | BH34: 82 | BM34: food | BN34: 59
AG35: sao luis | AH35: 310 | AM35: sao luis | AN35: 310 | AQ35: itacoatiara | AR35: 46 | AW35: duartina | AX35: 5.3333333 | BG35: books_technical | BH35: 80 | BM35: fashion_shoes | BN35: 61
AG36: piracicaba | AH36: 308 | AM36: piracicaba | AN36: 308 | AQ36: riacho de santo antonio | AR36: 45 | AW36: inubia paulista | AX36: 5.3333333 | BG36: air_conditioning | BH36: 77 | BM36: tablets_printing_image | BN36: 64
AG37: sao jose do rio preto | AH37: 291 | AM37: sao jose do rio preto | AN37: 291 | AQ37: joselandia | AR37: 45 | AW37: anta | AX37: 5.5 | BG37: home_appliances_2 | BH37: 72 | BM37: food_drink | BN37: 65
AG38: vila velha | AH38: 275 | AM38: vila velha | AN38: 275 | AQ38: chaveslandia | AR38: 45 | AW38: canitar | AX38: 5.5 | BG38: agro_industry_and_commerce | BH38: 67 | BM38: agro_industry_and_commerce | BN38: 67
AG39: diadema | AH39: 274 | AM39: diadema | AN39: 274 | AQ39: sao pedro do iguacu | AR39: 44 | AW39: igaracu do tiete | AX39: 5.5 | BG39: food_drink | BH39: 65 | BM39: home_appliances_2 | BN39: 72
AG40: campo grande | AH40: 271 | AM40: campo grande | AN40: 271 | AQ40: japi | AR40: 44 | AW40: sao miguel do tapuio | AX40: 5.5 | BG40: tablets_printing_image | BH40: 64 | BM40: air_conditioning | BN40: 77
AG41: carapicuiba | AH41: 268 | AM41: carapicuiba | AN41: 268 | AQ41: america dourada | AR41: 44 | AW41: biritiba-mirim | AX41: 5.5714286 | BG41: fashion_shoes | BH41: 61 | BM41: books_technical | BN41: 80
...

Sheet helper
A1: KPI's
A2: particulars | B2: values
A3: total ordes | B3: =_xlfn.XLOOKUP("Grand Total",pivot!A3:A10,pivot!B3:B10,0) -> 89315
A4: delivered | B4: =_xlfn.XLOOKUP(A4,pivot!A3:A8,pivot!B3:B8,0) -> 87428
A5: canceled | B5: =_xlfn.XLOOKUP(A5,pivot!A3:A8,pivot!B3:B8,0) -> 409
A6: processing | B6: =SUM(_xlfn.XLOOKUP("approved",pivot!A3:A8,pivot!B3:B8,0),_xlfn.XLOOKUP("invoiced",pivot!A3:A8,pivot!B3:B8,0),_xlfn.XLOOKUP("processing",pivot!A3:A8,pivot!B3:B8,0),_xlfn.XLOOKUP("shipped",pivot!A3:A8,pivot!B3:B8,0)) -> 1476
A7: avg delivery time | B7: =IF(pivot!E3=0,"no data",pivot!E3) -> 12.395438
A8: on time delivery | B8: =IFERROR(_xlfn.XLOOKUP(A8,pivot!H3:H4,pivot!I3:I4)/_xlfn.XLOOKUP("Grand Total",pivot!H3:H5,pivot!I3:I5),"no data") -> 0.92292999
A9: total sales | B9: =pivot!L3 -> 30447873
A10: avg sales | B10: =pivot!O3 -> 340.90054
A11: low orders state | B11: =pivot!AC3 -> Acre
A12: low used payment type | B12: =pivot!BQ3 -> credit_card
A13: low selling product | B13: =pivot!BM3 -> security_and_services
A14: late delivery | B14: =IFERROR(_xlfn.XLOOKUP(A14,pivot!H3:H4,pivot!I3:I4)/_xlfn.XLOOKUP("Grand Total",pivot!H3:H5,pivot!I3:I5),"No data") -> 0.077070013

Sheet Dashboard
